<?xml version="1.0"?>
<sdf version="1.10">
  <model name="fleet_bot">
    <pose>0 0 0.18 0 0 0</pose>
    <link name="base_link">
      <inertial><mass>12.0</mass><inertia><ixx>0.35</ixx><iyy>0.35</iyy><izz>0.45</izz></inertia></inertial>
      <collision name="body_collision"><geometry><box><size>0.55 0.42 0.22</size></box></geometry></collision>
      <visual name="body_visual"><geometry><box><size>0.55 0.42 0.22</size></box></geometry><material><ambient>0.1 0.35 0.8 1</ambient><diffuse>0.1 0.35 0.8 1</diffuse></material></visual>
      <sensor name="lidar" type="gpu_lidar">
        <pose>0.08 0 0.20 0 0 0</pose>
        <topic>scan</topic>
        <update_rate>10</update_rate>
        <ray><scan><horizontal><samples>360</samples><resolution>1</resolution><min_angle>-3.14159</min_angle><max_angle>3.14159</max_angle></horizontal></scan><range><min>0.12</min><max>8.0</max><resolution>0.02</resolution></range></ray>
        <always_on>true</always_on><visualize>true</visualize>
      </sensor>
    </link>
    <link name="left_wheel"><pose>0 0.25 0 1.5708 0 0</pose><collision name="c"><geometry><cylinder><radius>0.09</radius><length>0.04</length></cylinder></geometry></collision><visual name="v"><geometry><cylinder><radius>0.09</radius><length>0.04</length></cylinder></geometry></visual></link>
    <link name="right_wheel"><pose>0 -0.25 0 1.5708 0 0</pose><collision name="c"><geometry><cylinder><radius>0.09</radius><length>0.04</length></cylinder></geometry></collision><visual name="v"><geometry><cylinder><radius>0.09</radius><length>0.04</length></cylinder></geometry></visual></link>
    <joint name="left_wheel_joint" type="revolute"><parent>base_link</parent><child>left_wheel</child><axis><xyz>0 1 0</xyz></axis></joint>
    <joint name="right_wheel_joint" type="revolute"><parent>base_link</parent><child>right_wheel</child><axis><xyz>0 1 0</xyz></axis></joint>
    <plugin filename="gz-sim-diff-drive-system" name="gz::sim::systems::DiffDrive">
      <left_joint>left_wheel_joint</left_joint><right_joint>right_wheel_joint</right_joint>
      <wheel_separation>0.50</wheel_separation><wheel_radius>0.09</wheel_radius>
      <topic>cmd_vel</topic><odom_topic>odom</odom_topic><frame_id>odom</frame_id><child_frame_id>base_link</child_frame_id>
    </plugin>
    <plugin filename="gz-sim-joint-state-publisher-system" name="gz::sim::systems::JointStatePublisher"/>
  </model>
</sdf>
